<?xml version="1.0" ?>
<sdf version="1.7">
  <model name="simple_humanoid">
    <!-- Base Link -->
    <link name="base_link">
      <visual name="base_visual">
        <geometry>
          <box>
            <size>0.3 0.2 0.1</size>
          </box>
        </geometry>
        <material>
          <ambient>0 0 1 1</ambient>
          <diffuse>0 0 1 1</diffuse>
        </material>
      </visual>
      <collision name="base_collision">
        <geometry>
          <box>
            <size>0.3 0.2 0.1</size>
          </box>
        </geometry>
      </collision>
      <inertial>
        <mass>5.0</mass>
        <inertia>
          <ixx>0.1</ixx>
          <ixy>0.0</ixy>
          <ixz>0.0</ixz>
          <iyy>0.1</iyy>
          <iyz>0.0</iyz>
          <izz>0.1</izz>
        </inertia>
      </inertial>
    </link>

    <!-- Head -->
    <link name="head">
      <visual name="head_visual">
        <geometry>
          <sphere>
            <radius>0.1</radius>
          </sphere>
        </geometry>
        <material>
          <ambient>1 1 1 1</ambient>
          <diffuse>1 1 1 1</diffuse>
        </material>
      </visual>
      <collision name="head_collision">
        <geometry>
          <sphere>
            <radius>0.1</radius>
          </sphere>
        </geometry>
      </collision>
      <inertial>
        <mass>1.0</mass>
        <inertia>
          <ixx>0.001</ixx>
          <ixy>0.0</ixy>
          <ixz>0.0</ixz>
          <iyy>0.001</iyy>
          <iyz>0.0</iyz>
          <izz>0.001</izz>
        </inertia>
      </inertial>
    </link>

    <joint name="head_joint" type="fixed">
      <parent>base_link</parent>
      <child>head</child>
      <pose>0 0 0.15 0 0 0</pose>
    </joint>

    <!-- Left Arm -->
    <link name="left_upper_arm">
      <visual name="left_upper_arm_visual">
        <geometry>
          <cylinder>
            <length>0.2</length>
            <radius>0.03</radius>
          </cylinder>
        </geometry>
        <material>
          <ambient>1 0 0 1</ambient>
          <diffuse>1 0 0 1</diffuse>
        </material>
      </visual>
      <collision name="left_upper_arm_collision">
        <geometry>
          <cylinder>
            <length>0.2</length>
            <radius>0.03</radius>
          </cylinder>
        </geometry>
      </collision>
      <inertial>
        <mass>0.5</mass>
        <inertia>
          <ixx>0.001</ixx>
          <ixy>0.0</ixy>
          <ixz>0.0</ixz>
          <iyy>0.001</iyy>
          <iyz>0.0</iyz>
          <izz>0.001</izz>
        </inertia>
      </inertial>
    </link>

    <joint name="left_shoulder_joint" type="revolute">
      <parent>base_link</parent>
      <child>left_upper_arm</child>
      <pose>0.18 0.1 0 0 0 0</pose>
      <axis>
        <xyz>0 1 0</xyz>
        <limit>
          <lower>-1.57</lower>
          <upper>1.57</upper>
        </limit>
      </axis>
    </joint>

    <link name="left_lower_arm">
      <visual name="left_lower_arm_visual">
        <geometry>
          <cylinder>
            <length>0.15</length>
            <radius>0.025</radius>
          </cylinder>
        </geometry>
        <material>
          <ambient>1 0 0 1</ambient>
          <diffuse>1 0 0 1</diffuse>
        </material>
      </visual>
      <collision name="left_lower_arm_collision">
        <geometry>
          <cylinder>
            <length>0.15</length>
            <radius>0.025</radius>
          </cylinder>
        </geometry>
      </collision>
      <inertial>
        <mass>0.3</mass>
        <inertia>
          <ixx>0.001</ixx>
          <ixy>0.0</ixy>
          <ixz>0.0</ixz>
          <iyy>0.001</iyy>
          <iyz>0.0</iyz>
          <izz>0.001</izz>
        </inertia>
      </inertial>
    </link>

    <joint name="left_elbow_joint" type="revolute">
      <parent>left_upper_arm</parent>
      <child>left_lower_arm</child>
      <pose>0 0 -0.175 0 0 0</pose>
      <axis>
        <xyz>0 1 0</xyz>
        <limit>
          <lower>-1.57</lower>
          <upper>1.57</upper>
        </limit>
      </axis>
    </joint>

    <!-- Right Arm -->
    <link name="right_upper_arm">
      <visual name="right_upper_arm_visual">
        <geometry>
          <cylinder>
            <length>0.2</length>
            <radius>0.03</radius>
          </cylinder>
        </geometry>
        <material>
          <ambient>1 0 0 1</ambient>
          <diffuse>1 0 0 1</diffuse>
        </material>
      </visual>
      <collision name="right_upper_arm_collision">
        <geometry>
          <cylinder>
            <length>0.2</length>
            <radius>0.03</radius>
          </cylinder>
        </geometry>
      </collision>
      <inertial>
        <mass>0.5</mass>
        <inertia>
          <ixx>0.001</ixx>
          <ixy>0.0</ixy>
          <ixz>0.0</ixz>
          <iyy>0.001</iyy>
          <iyz>0.0</iyz>
          <izz>0.001</izz>
        </inertia>
      </inertial>
    </link>

    <joint name="right_shoulder_joint" type="revolute">
      <parent>base_link</parent>
      <child>right_upper_arm</child>
      <pose>0.18 -0.1 0 0 0 0</pose>
      <axis>
        <xyz>0 1 0</xyz>
        <limit>
          <lower>-1.57</lower>
          <upper>1.57</upper>
        </limit>
      </axis>
    </joint>

    <link name="right_lower_arm">
      <visual name="right_lower_arm_visual">
        <geometry>
          <cylinder>
            <length>0.15</length>
            <radius>0.025</radius>
          </cylinder>
        </geometry>
        <material>
          <ambient>1 0 0 1</ambient>
          <diffuse>1 0 0 1</diffuse>
        </material>
      </visual>
      <collision name="right_lower_arm_collision">
        <geometry>
          <cylinder>
            <length>0.15</length>
            <radius>0.025</radius>
          </cylinder>
        </geometry>
      </collision>
      <inertial>
        <mass>0.3</mass>
        <inertia>
          <ixx>0.001</ixx>
          <ixy>0.0</ixy>
          <ixz>0.0</ixz>
          <iyy>0.001</iyy>
          <iyz>0.0</iyz>
          <izz>0.001</izz>
        </inertia>
      </inertial>
    </link>

    <joint name="right_elbow_joint" type="revolute">
      <parent>right_upper_arm</parent>
      <child>right_lower_arm</child>
      <pose>0 0 -0.175 0 0 0</pose>
      <axis>
        <xyz>0 1 0</xyz>
        <limit>
          <lower>-1.57</lower>
          <upper>1.57</upper>
        </limit>
      </axis>
    </joint>

    <!-- Left Leg -->
    <link name="left_upper_leg">
      <visual name="left_upper_leg_visual">
        <geometry>
          <cylinder>
            <length>0.25</length>
            <radius>0.04</radius>
          </cylinder>
        </geometry>
        <material>
          <ambient>0 1 0 1</ambient>
          <diffuse>0 1 0 1</diffuse>
        </material>
      </visual>
      <collision name="left_upper_leg_collision">
        <geometry>
          <cylinder>
            <length>0.25</length>
            <radius>0.04</radius>
          </cylinder>
        </geometry>
      </collision>
      <inertial>
        <mass>0.8</mass>
        <inertia>
          <ixx>0.002</ixx>
          <ixy>0.0</ixy>
          <ixz>0.0</ixz>
          <iyy>0.002</iyy>
          <iyz>0.0</iyz>
          <izz>0.002</izz>
        </inertia>
      </inertial>
    </link>

    <joint name="left_hip_joint" type="revolute">
      <parent>base_link</parent>
      <child>left_upper_leg</child>
      <pose>-0.1 -0.05 -0.05 0 0 0</pose>
      <axis>
        <xyz>0 1 0</xyz>
        <limit>
          <lower>-1.57</lower>
          <upper>1.57</upper>
        </limit>
      </axis>
    </joint>

    <link name="left_lower_leg">
      <visual name="left_lower_leg_visual">
        <geometry>
          <cylinder>
            <length>0.25</length>
            <radius>0.035</radius>
          </cylinder>
        </geometry>
        <material>
          <ambient>0 1 0 1</ambient>
          <diffuse>0 1 0 1</diffuse>
        </material>
      </visual>
      <collision name="left_lower_leg_collision">
        <geometry>
          <cylinder>
            <length>0.25</length>
            <radius>0.035</radius>
          </cylinder>
        </geometry>
      </collision>
      <inertial>
        <mass>0.6</mass>
        <inertia>
          <ixx>0.002</ixx>
          <ixy>0.0</ixy>
          <ixz>0.0</ixz>
          <iyy>0.002</iyy>
          <iyz>0.0</iyz>
          <izz>0.002</izz>
        </inertia>
      </inertial>
    </link>

    <joint name="left_knee_joint" type="revolute">
      <parent>left_upper_leg</parent>
      <child>left_lower_leg</child>
      <pose>0 0 -0.2 0 0 0</pose>
      <axis>
        <xyz>0 1 0</xyz>
        <limit>
          <lower>-1.57</lower>
          <upper>1.57</upper>
        </limit>
      </axis>
    </joint>

    <!-- Right Leg -->
    <link name="right_upper_leg">
      <visual name="right_upper_leg_visual">
        <geometry>
          <cylinder>
            <length>0.25</length>
            <radius>0.04</radius>
          </cylinder>
        </geometry>
        <material>
          <ambient>0 1 0 1</ambient>
          <diffuse>0 1 0 1</diffuse>
        </material>
      </visual>
      <collision name="right_upper_leg_collision">
        <geometry>
          <cylinder>
            <length>0.25</length>
            <radius>0.04</radius>
          </cylinder>
        </geometry>
      </collision>
      <inertial>
        <mass>0.8</mass>
        <inertia>
          <ixx>0.002</ixx>
          <ixy>0.0</ixy>
          <ixz>0.0</ixz>
          <iyy>0.002</iyy>
          <iyz>0.0</iyz>
          <izz>0.002</izz>
        </inertia>
      </inertial>
    </link>

    <joint name="right_hip_joint" type="revolute">
      <parent>base_link</parent>
      <child>right_upper_leg</child>
      <pose>-0.1 0.05 -0.05 0 0 0</pose>
      <axis>
        <xyz>0 1 0</xyz>
        <limit>
          <lower>-1.57</lower>
          <upper>1.57</upper>
        </limit>
      </axis>
    </joint>

    <link name="right_lower_leg">
      <visual name="right_lower_leg_visual">
        <geometry>
          <cylinder>
            <length>0.25</length>
            <radius>0.035</radius>
          </cylinder>
        </geometry>
        <material>
          <ambient>0 1 0 1</ambient>
          <diffuse>0 1 0 1</diffuse>
        </material>
      </visual>
      <collision name="right_lower_leg_collision">
        <geometry>
          <cylinder>
            <length>0.25</length>
            <radius>0.035</radius>
          </cylinder>
        </geometry>
      </collision>
      <inertial>
        <mass>0.6</mass>
        <inertia>
          <ixx>0.002</ixx>
          <ixy>0.0</ixy>
          <ixz>0.0</ixz>
          <iyy>0.002</iyy>
          <iyz>0.0</iyz>
          <izz>0.002</izz>
        </inertia>
      </inertial>
    </link>

    <joint name="right_knee_joint" type="revolute">
      <parent>right_upper_leg</parent>
      <child>right_lower_leg</child>
      <pose>0 0 -0.2 0 0 0</pose>
      <axis>
        <xyz>0 1 0</xyz>
        <limit>
          <lower>-1.57</lower>
          <upper>1.57</upper>
        </limit>
      </axis>
    </joint>

  </model>
</sdf>